Workbook
Name Slicer_Diabetes_Status: #N/A
Name Slicer_Hospital_tier: #N/A
Name Slicer_Weight_Status: #N/A

Sheet Customer Names
A1: Customer ID | B1: name
A2: Id1 | B2: Hawks, Ms. Kelly
A3: Id2 | B3: Lehner, Mr. Matthew D
A4: Id3 | B4: Lu, Mr. Phil
A5: Id4 | B5: Osborne, Ms. Kelsey
A6: Id5 | B6: Kadala, Ms. Kristyn
A7: Id6 | B7: Baker, Mr. Russell B.
A8: Id7 | B8: Macpherson, Mr. Scott
A9: Id8 | B9: Hallman, Mr. Stephen
A10: Id9 | B10: Moran, Mr. Patrick R.
A11: Id10 | B11: Benner, Ms. Brooke N.
A12: Id11 | B12: Fierro Vargas, Ms. Paola Andrea
... A2336: Id2335 | B2336: German, Mr. Aaron K

Sheet Medical Examinations
A1: Customer ID | B1: BMI | C1: HBA1C | D1: Heart Issues | E1: Any Transplants | F1: Cancer history | G1: NumberOfMajorSurgeries | H1: smoker
A2: Id1 | B2: 47.41 | C2: 7.47 | D2: No | E2: No | F2: No | G2: No major surgery | H2: yes
A3: Id2 | B3: 30.36 | C3: 5.77 | D3: No | E3: No | F3: No | G3: No major surgery | H3: yes
A4: Id3 | B4: 34.485 | C4: 11.87 | D4: yes | E4: No | F4: No | G4: 2 | H4: yes
A5: Id4 | B5: 38.095 | C5: 6.05 | D5: No | E5: No | F5: No | G5: No major surgery | H5: yes
A6: Id5 | B6: 35.53 | C6: 5.45 | D6: No | E6: No | F6: No | G6: No major surgery | H6: yes
A7: Id6 | B7: 32.8 | C7: 6.59 | D7: No | E7: No | F7: No | G7: No major surgery | H7: yes
A8: Id7 | B8: 36.4 | C8: 6.07 | D8: No | E8: No | F8: No | G8: No major surgery | H8: yes
A9: Id8 | B9: 36.96 | C9: 7.93 | D9: No | E9: No | F9: No | G9: 3 | H9: yes
A10: Id9 | B10: 41.14 | C10: 9.58 | D10: yes | E10: No | F10: Yes | G10: 1 | H10: yes
A11: Id10 | B11: 38.06 | C11: 10.79 | D11: No | E11: No | F11: No | G11: No major surgery | H11: yes
A12: Id11 | B12: 37.7 | C12: 5.96 | D12: yes | E12: No | F12: No | G12: 2 | H12: yes
A13: Id12 | B13: 42.13 | C13: 11.9 | D13: No | E13: No | F13: No | G13: No major surgery | H13: yes
A14: Id13 | B14: 40.92 | C14: 8.41 | D14: No | E14: No | F14: No | G14: No major surgery | H14: yes
A15: Id14 | B15: 40.565 | C15: 7.02 | D15: No | E15: No | F15: No | G15: No major surgery | H15: yes
A16: Id15 | B16: 36.385 | C16: 7.59 | D16: yes | E16: No | F16: No | G16: 2 | H16: yes
A17: Id16 | B17: 39.9 | C17: 11.32 | D17: No | E17: No | F17: No | G17: No major surgery | H17: yes
A18: Id17 | B18: 33.8 | C18: 7.67 | D18: No | E18: No | F18: No | G18: 3 | H18: yes
A19: Id18 | B19: 36.765 | C19: 7.29 | D19: yes | E19: No | F19: Yes | G19: 1 | H19: yes
A20: Id19 | B20: 36.955 | C20: 4.72 | D20: yes | E20: No | F20: No | G20: 1 | H20: yes
A21: Id20 | B21: 42.9 | C21: 11.41 | D21: No | E21: No | F21: No | G21: No major surgery | H21: yes
A22: Id21 | B22: 36.3 | C22: 11.5 | D22: yes | E22: No | F22: No | G22: 2 | H22: yes
A23: Id22 | B23: 32.2 | C23: 6.22 | D23: yes | E23: No | F23: No | G23: 2 | H23: yes
A24: Id23 | B24: 31.3 | C24: 11.38 | D24: No | E24: No | F24: No | G24: 3 | H24: yes
A25: Id24 | B25: 41.8 | C25: 7.89 | D25: yes | E25: No | F25: No | G25: 2 | H25: yes
A26: Id25 | B26: 35.09 | C26: 4.38 | D26: yes | E26: No | F26: No | G26: 2 | H26: yes
A27: Id26 | B27: 33.88 | C27: 7.01 | D27: No | E27: No | F27: No | G27: 3 | H27: yes
A28: Id27 | B28: 30.875 | C28: 11.88 | D28: No | E28: No | F28: No | G28: No major surgery | H28: yes
A29: Id28 | B29: 36.86 | C29: 5.19 | D29: yes | E29: No | F29: Yes | G29: 1 | H29: yes
A30: Id29 | B30: 35.86 | C30: 6.74 | D30: yes | E30: No | F30: No | G30: 2 | H30: yes
A31: Id30 | B31: 37.05 | C31: 8.44 | D31: No | E31: No | F31: No | G31: No major surgery | H31: yes
A32: Id31 | B32: 43.89 | C32: 8.71 | D32: No | E32: No | F32: No | G32: No major surgery | H32: yes
A33: Id32 | B33: 42.35 | C33: 5.08 | D33: yes | E33: No | F33: No | G33: No major surgery | H33: yes
A34: Id33 | B34: 31.35 | C34: 6.86 | D34: No | E34: No | F34: No | G34: No major surgery | H34: yes
A35: Id34 | B35: 47.6 | C35: 5.95 | D35: yes | E35: No | F35: No | G35: No major surgery | H35: yes
A36: Id35 | B36: 46.2 | C36: 6.09 | D36: No | E36: No | F36: Yes | G36: 1 | H36: yes
A37: Id36 | B37: 32.015 | C37: 11.75 | D37: No | E37: No | F37: No | G37: No major surgery | H37: yes
A38: Id37 | B38: 40.565 | C38: 7.37 | D38: No | E38: No | F38: No | G38: No major surgery | H38: yes
A39: Id38 | B39: 32.45 | C39: 11.91 | D39: No | E39: No | F39: No | G39: No major surgery | H39: yes
A40: Id39 | B40: 34.96 | C40: 6.52 | D40: No | E40: No | F40: No | G40: No major surgery | H40: yes
...

Sheet Hospitalisation Details
A1: Customer ID | B1: year | C1: month | D1: date | E1: children | F1: charges | G1: Hospital tier | H1: City tier | I1: State ID
A2: Id2335 | B2: 1992 | C2: Jul | D2: 9 | E2: 0 | F2: 563.84 | G2: tier - 2 | H2: tier - 3 | I2: R1013
A3: Id2334 | B3: 1992 | C3: Nov | D3: 30 | E3: 0 | F3: 570.62 | G3: tier - 2 | H3: tier - 1 | I3: R1013
A4: Id2333 | B4: 1993 | C4: Jun | D4: 30 | E4: 0 | F4: 600 | G4: tier - 2 | H4: tier - 1 | I4: R1013
A5: Id2332 | B5: 1992 | C5: Sep | D5: 13 | E5: 0 | F5: 604.54 | G5: tier - 3 | H5: tier - 3 | I5: R1013
A6: Id2331 | B6: 1998 | C6: Jul | D6: 27 | E6: 0 | F6: 637.26 | G6: tier - 3 | H6: tier - 3 | I6: R1013
A7: Id2330 | B7: 2001 | C7: Nov | D7: 20 | E7: 0 | F7: 646.14 | G7: tier - 3 | H7: tier - 3 | I7: R1012
A8: Id2329 | B8: 1993 | C8: Jun | D8: 1 | E8: 0 | F8: 650 | G8: tier - 3 | H8: tier - 3 | I8: R1013
A9: Id2328 | B9: 1995 | C9: Jul | D9: 4 | E9: 0 | F9: 650 | G9: tier - 3 | H9: tier - 3 | I9: R1013
A10: Id2327 | B10: 2002 | C10: Nov | D10: 29 | E10: 0 | F10: 668 | G10: tier - 3 | H10: tier - 2 | I10: R1012
A11: Id2326 | B11: 1997 | C11: Nov | D11: 9 | E11: 0 | F11: 670 | G11: tier - 3 | H11: tier - 3 | I11: R1013
A12: Id2325 | B12: 2001 | C12: Sep | D12: 12 | E12: 0 | F12: 687.54 | G12: tier - 3 | H12: tier - 2 | I12: R1013
A13: Id2324 | B13: 1999 | C13: Dec | D13: 26 | E13: 0 | F13: 700 | G13: ? | H13: tier - 3 | I13: R1013
... A1050: Id1290 | B1050: 1977 | C1050: Jul | D1050: 26 | E1050: 2 | F1050: 8527.53 | G1050: tier - 2 | H1050: tier - 2 | I1050: R1013
A1051: Id1289 | B1051: ? | C1051: Jul | D1051: 24 | E1051: 0 | F1051: 8534.67 | G1051: tier - 2 | H1051: tier - 3 | I1051: R1024
A1052: Id1288 | B1052: 1981 | C1052: Dec | D1052: 27 | E1052: 3 | F1052: 8538.29 | G1052: tier - 2 | H1052: tier - 3 | I1052: R1024
A1053: Id1287 | B1053: 1975 | C1053: Nov | D1053: 6 | E1053: 1 | F1053: 8539.67 | G1053: tier - 2 | H1053: tier - 3 | I1053: R1011
A1054: Id1286 | B1054: ? | C1054: Dec | D1054: 12 | E1054: 1 | F1054: 8547.69 | G1054: tier - 2 | H1054: tier - 1 | I1054: R1013
A1055: Id1285 | B1055: 1975 | C1055: Aug | D1055: 6 | E1055: 1 | F1055: 8551.35 | G1055: tier - 2 | H1055: tier - 2 | I1055: R1011
A1056: Id1284 | B1056: 1975 | C1056: Aug | D1056: 21 | E1056: 1 | F1056: 8556.91 | G1056: tier - 2 | H1056: tier - 1 | I1056: R1011
A1057: Id1283 | B1057: 1988 | C1057: Sep | D1057: 21 | E1057: 3 | F1057: 8567.25 | G1057: tier - 2 | H1057: tier - 1 | I1057: R1012
A1058: Id1282 | B1058: 1975 | C1058: Sep | D1058: 26 | E1058: 1 | F1058: 8569.86 | G1058: tier - 2 | H1058: tier - 3 | I1058: R1013
A1059: Id1281 | B1059: 1982 | C1059: Dec | D1059: 6 | E1059: 3 | F1059: 8572.04 | G1059: tier - 2 | H1059: tier - 2 | I1059: R1021
A1060: Id1280 | B1060: 1987 | C1060: Nov | D1060: 11 | E1060: 3 | F1060: 8573.3 | G1060: tier - 2 | H1060: tier - 2 | I1060: R1021
A1061: Id1279 | B1061: 1983 | C1061: Dec | D1061: 30 | E1061: 5 | F1061: 8582.3 | G1061: tier - 2 | H1061: tier - 1 | I1061: R1013
A1062: Id1278 | B1062: 1983 | C1062: Jul | D1062: 25 | E1062: 5 | F1062: 8596.83 | G1062: tier - 2 | H1062: tier - 3 | I1062: R1013
A1063: Id1277 | B1063: 1973 | C1063: Jul | D1063: 11 | E1063: 0 | F1063: 8601.33 | G1063: tier - 2 | H1063: tier - 1 | I1063: R1013
A1064: Id1276 | B1064: 1977 | C1064: Sep | D1064: 24 | E1064: 2 | F1064: 8603.82 | G1064: tier - 2 | H1064: tier - 1 | I1064: R1019
A1065: Id1275 | B1065: 1977 | C1065: Nov | D1065: 12 | E1065: 2 | F1065: 8604.48 | G1065: tier - 3 | H1065: tier - 2 | I1065: R1016
A1066: Id1274 | B1066: 1977 | C1066: Oct | D1066: 15 | E1066: 3 | F1066: 8605.36 | G1066: tier - 2 | H1066: tier - 2 | I1066: R1013
... A2344: Id1 | B2344: 1968 | C2344: Oct | D2344: 12 | E2344: 0 | F2344: 63770.43 | G2344: tier - 1 | H2344: tier - 3 | I2344: R1013

Sheet Data cleaning
P1: year | Q1: month | R1: State ID
B2: Number of missing values in each coloumn in medical examinations | J2: Number of missing values in each coloumn in hospitalisation details | P2: 1992 | Q2: Jul | R2: =IF('Hospitalisation Details'!I2="?","Unknown",'Hospitalisation Details'!I2) -> R1013
C3: Customer ID | D3: =COUNTIF('Medical Examinations'!B2:B2336,"?") -> 0 | K3: Customer ID | L3: =COUNTIF('Hospitalisation Details'!A2:A2344,"?") -> 6 | P3: 1992 | Q3: Nov | R3: =IF('Hospitalisation Details'!I3="?","Unknown",'Hospitalisation Details'!I3) -> R1013
C4: BMI | D4: =COUNTIF('Medical Examinations'!C1:C2336,"?") -> 0 | K4: year | L4: =COUNTIF('Hospitalisation Details'!B1:B2344,"?") -> 2 | P4: 1993 | Q4: Jun | R4: =IF('Hospitalisation Details'!I4="?","Unknown",'Hospitalisation Details'!I4) -> R1013
C5: HBA1C | D5: =COUNTIF('Medical Examinations'!C2:C2336,"?") -> 0 | K5: month | L5: =COUNTIF('Hospitalisation Details'!C2:C2344,"?") -> 3 | P5: 1992 | Q5: Sep | R5: =IF('Hospitalisation Details'!I5="?","Unknown",'Hospitalisation Details'!I5) -> R1013
C6: Heart Issues | D6: =COUNTIF('Medical Examinations'!E1:E2336,"?") -> 0 | K6: date | L6: =COUNTIF('Hospitalisation Details'!D1:D2344,"?") -> 0 | P6: 1998 | Q6: Jul | R6: =IF('Hospitalisation Details'!I6="?","Unknown",'Hospitalisation Details'!I6) -> R1013
C7: Any Transplants | D7: =COUNTIF('Medical Examinations'!F2:F2336,"?") -> 0 | K7: children | L7: =COUNTIF('Hospitalisation Details'!E2:E2344,"?") -> 0 | P7: 2001 | Q7: Nov | R7: =IF('Hospitalisation Details'!I7="?","Unknown",'Hospitalisation Details'!I7) -> R1012
C8: Cancer history | D8: =COUNTIF('Medical Examinations'!F1:F2336,"?") -> 0 | K8: charges | L8: =COUNTIF('Hospitalisation Details'!F1:F2344,"?") -> 0 | P8: 1993 | Q8: Jun | R8: =IF('Hospitalisation Details'!I8="?","Unknown",'Hospitalisation Details'!I8) -> R1013
C9: NumberOfMajorSurgeries | D9: =COUNTIF('Medical Examinations'!G2:G2336,"?") -> 0 | K9: Hospital tier | L9: =COUNTIF('Hospitalisation Details'!G2:G2344,"?") -> 1 | P9: 1995 | Q9: Jul | R9: =IF('Hospitalisation Details'!I9="?","Unknown",'Hospitalisation Details'!I9) -> R1013
C10: smoker | D10: =COUNTIF('Medical Examinations'!H1:H2336,"?") -> 2 | K10: City tier | L10: =COUNTIF('Hospitalisation Details'!H1:H2344,"?") -> 1 | P10: 2002 | Q10: Nov | R10: =IF('Hospitalisation Details'!I10="?","Unknown",'Hospitalisation Details'!I10) -> R1012
K11: State ID | L11: =COUNTIF('Hospitalisation Details'!I2:I2344,"?") -> 2 | P11: 1997 | Q11: Nov | R11: =IF('Hospitalisation Details'!I11="?","Unknown",'Hospitalisation Details'!I11) -> R1013
P12: 2001 | Q12: Sep | R12: =IF('Hospitalisation Details'!I12="?","Unknown",'Hospitalisation Details'!I12) -> R1013
C13: Rounded average | D13: =ROUND(AVERAGE('Hospitalisation Details'!B:B),0) -> 1983 | P13: 1999 | Q13: Dec | R13: =IF('Hospitalisation Details'!I13="?","Unknown",'Hospitalisation Details'!I13) -> R1013
P14: 1999 | Q14: Dec | R14: =IF('Hospitalisation Details'!I14="?","Unknown",'Hospitalisation Details'!I14) -> R1013
P15: 2002 | Q15: Sep | R15: =IF('Hospitalisation Details'!I15="?","Unknown",'Hospitalisation Details'!I15) -> R1012
B16: Unique value of smoker,hospital tier and city tier | J16: Count of smoker hospital tier and city tier | P16: 1993 | Q16: Aug | R16: =IF('Hospitalisation Details'!I16="?","Unknown",'Hospitalisation Details'!I16) -> R1013
B17: smoker | C17: Hospital tier | D17: City tier | J17: smoker | K17: Hospital tier | L17: City tier | P17: 1996 | Q17: Oct | R17: =IF('Hospitalisation Details'!I17="?","Unknown",'Hospitalisation Details'!I17) -> R1013
B18: {=_xlfn.UNIQUE('Medical Examinations'!H2:H2336)} -> yes | C18: {=_xlfn.UNIQUE('Hospitalisation Details'!G2:G2344)} -> tier - 2 | D18: {=_xlfn.UNIQUE('Hospitalisation Details'!H2:H2344)} -> tier - 3 | J18: =COUNTIF('Medical Examinations'!H2:H2336,'Data cleaning'!B18) -> 488 | K18: =COUNTIF('Hospitalisation Details'!G1:G2344,'Data cleaning'!C18) -> 1339 | L18: =COUNTIF('Hospitalisation Details'!H1:H2344,'Data cleaning'!D18) -> 796 | P18: 1993 | Q18: Jun | R18: =IF('Hospitalisation Details'!I18="?","Unknown",'Hospitalisation Details'!I18) -> R1013
B19: No | C19: tier - 3 | D19: tier - 1 | J19: =COUNTIF('Medical Examinations'!H1:H2336,'Data cleaning'!B19) -> 1845 | K19: =COUNTIF('Hospitalisation Details'!G2:G2344,'Data cleaning'!C19) -> 694 | L19: =COUNTIF('Hospitalisation Details'!H2:H2344,'Data cleaning'!D19) -> 734 | P19: 1996 | Q19: Sep | R19: =IF('Hospitalisation Details'!I19="?","Unknown",'Hospitalisation Details'!I19) -> R1012
B20: ? | C20: ? | D20: tier - 2 | J20: =COUNTIF('Medical Examinations'!H2:H2336,'Data cleaning'!B20) -> 2 | K20: =COUNTIF('Hospitalisation Details'!G1:G2344,'Data cleaning'!C20) -> 1 | L20: =COUNTIF('Hospitalisation Details'!H1:H2344,'Data cleaning'!D20) -> 812 | P20: 1995 | Q20: Dec | R20: =IF('Hospitalisation Details'!I20="?","Unknown",'Hospitalisation Details'!I20) -> R1013
C21: tier - 1 | D21: ? | K21: =COUNTIF('Hospitalisation Details'!G2:G2344,'Data cleaning'!C21) -> 309 | L21: =COUNTIF('Hospitalisation Details'!H2:H2344,'Data cleaning'!D21) -> 1 | P21: 2004 | Q21: Oct | R21: =IF('Hospitalisation Details'!I21="?","Unknown",'Hospitalisation Details'!I21) -> R1011
P22: 2000 | Q22: Nov | R22: =IF('Hospitalisation Details'!I22="?","Unknown",'Hospitalisation Details'!I22) -> R1013
B23: The most frequently occuring values in smoker | D23: 1845(No) | P23: 1993 | Q23: Nov | R23: =IF('Hospitalisation Details'!I23="?","Unknown",'Hospitalisation Details'!I23) -> R1013
B24: The most frequently occuring values in Hos tier | D24: 1339(tier2) | P24: 1994 | Q24: Oct | R24: =IF('Hospitalisation Details'!I24="?","Unknown",'Hospitalisation Details'!I24) -> R1013
B25: The most frequently occuring values in City tier | D25: 812(tier2) | P25: 1995 | Q25: Oct | R25: =IF('Hospitalisation Details'!I25="?","Unknown",'Hospitalisation Details'!I25) -> R1013
P26: 2001 | Q26: Aug | R26: =IF('Hospitalisation Details'!I26="?","Unknown",'Hospitalisation Details'!I26) -> R1013
P27: 1994 | Q27: Nov | R27: =IF('Hospitalisation Details'!I27="?","Unknown",'Hospitalisation Details'!I27) -> R1013
P28: 2000 | Q28: Oct | R28: =IF('Hospitalisation Details'!I28="?","Unknown",'Hospitalisation Details'!I28) -> R1013
P29: 1999 | Q29: Aug | R29: =IF('Hospitalisation Details'!I29="?","Unknown",'Hospitalisation Details'!I29) -> R1013
P30: 1995 | Q30: Oct | R30: =IF('Hospitalisation Details'!I30="?","Unknown",'Hospitalisation Details'!I30) -> R1013
P31: 1994 | Q31: Nov | R31: =IF('Hospitalisation Details'!I31="?","Unknown",'Hospitalisation Details'!I31) -> R1013
P32: 2002 | Q32: Jul | R32: =IF('Hospitalisation Details'!I32="?","Unknown",'Hospitalisation Details'!I32) -> R1013
P33: 2002 | Q33: Jul | R33: =IF('Hospitalisation Details'!I33="?","Unknown",'Hospitalisation Details'!I33) -> R1012
P34: 1995 | Q34: Jun | R34: =IF('Hospitalisation Details'!I34="?","Unknown",'Hospitalisation Details'!I34) -> R1013
P35: 1993 | Q35: Sep | R35: =IF('Hospitalisation Details'!I35="?","Unknown",'Hospitalisation Details'!I35) -> R1013
P36: 2004 | Q36: Aug | R36: =IF('Hospitalisation Details'!I36="?","Unknown",'Hospitalisation Details'!I36) -> R1013
P37: 1997 | Q37: Aug | R37: =IF('Hospitalisation Details'!I37="?","Unknown",'Hospitalisation Details'!I37) -> R1013
... P2344: 1968 | Q2344: Oct | R2344: =IF('Hospitalisation Details'!I2344="?","Unknown",'Hospitalisation Details'!I2344) -> R1013

Sheet Split_Neames
A1: name | E1: Last Name | F1: TITLE | G1: First Name | I1: First Name
A2: Hawks, Ms. Kelly | E2: Hawks | F2: Ms | G2: Kelly | I2: =_xlfn.TEXTJOIN("",TRUE,G2) -> Kelly
A3: Lehner, Mr. Matthew D | E3: Lehner | F3: Mr | G3: Matthew D | I3: =_xlfn.TEXTJOIN("",TRUE,G3) -> Matthew D
A4: Lu, Mr. Phil | E4: Lu | F4: Mr | G4: Phil | I4: =_xlfn.TEXTJOIN("",TRUE,G4) -> Phil
A5: Osborne, Ms. Kelsey | E5: Osborne | F5: Ms | G5: Kelsey | I5: =_xlfn.TEXTJOIN("",TRUE,G5) -> Kelsey
A6: Kadala, Ms. Kristyn | E6: Kadala | F6: Ms | G6: Kristyn | I6: =_xlfn.TEXTJOIN("",TRUE,G6) -> Kristyn
A7: Baker, Mr. Russell B. | E7: Baker | F7: Mr | G7: Russell B | I7: =_xlfn.TEXTJOIN("",TRUE,G7) -> Russell B
A8: Macpherson, Mr. Scott | E8: Macpherson | F8: Mr | G8: Scott | I8: =_xlfn.TEXTJOIN("",TRUE,G8) -> Scott
A9: Hallman, Mr. Stephen | E9: Hallman | F9: Mr | G9: Stephen | I9: =_xlfn.TEXTJOIN("",TRUE,G9) -> Stephen
A10: Moran, Mr. Patrick R. | E10: Moran | F10: Mr | G10: Patrick R | I10: =_xlfn.TEXTJOIN("",TRUE,G10) -> Patrick R
A11: Benner, Ms. Brooke N. | E11: Benner | F11: Ms | G11: Brooke N | I11: =_xlfn.TEXTJOIN("",TRUE,G11) -> Brooke N
A12: Fierro Vargas, Ms. Paola Andrea | E12: Fierro Vargas | F12: Ms | G12: Paola Andrea | I12: =_xlfn.TEXTJOIN("",TRUE,G12) -> Paola Andrea
A13: Franz, Mr. David | E13: Franz | F13: Mr | G13: David | I13: =_xlfn.TEXTJOIN("",TRUE,G13) -> David
... A72: Turner, Mr. Jeff | E72: Turner | F72: Mr | G72: Jeff | I72: =_xlfn.TEXTJOIN("",TRUE,G72) -> Jeff
A73: Rangel, Mr. Elenilton V. Sr. | E73: Rangel | F73: Mr | G73: Elenilton V | H73: Sr | I73: =_xlfn.TEXTJOIN("",TRUE,G73) -> Elenilton V
A74: Lacey, Ms. Maurya | E74: Lacey | F74: Ms | G74: Maurya | I74: =_xlfn.TEXTJOIN("",TRUE,G74) -> Maurya
A75: Stiger, Ms. Samantha C | E75: Stiger | F75: Ms | G75: Samantha C | I75: =_xlfn.TEXTJOIN("",TRUE,G75) -> Samantha C
A76: Caldwell, Ms. Bethany A | E76: Caldwell | F76: Ms | G76: Bethany A | I76: =_xlfn.TEXTJOIN("",TRUE,G76) -> Bethany A
A77: Marmillod, Mr. Yves | E77: Marmillod | F77: Mr | G77: Yves | I77: =_xlfn.TEXTJOIN("",TRUE,G77) -> Yves
A78: Cloutier-Simons, Ms. Danielle | E78: Cloutier-Simons | F78: Ms | G78: Danielle | I78: =_xlfn.TEXTJOIN("",TRUE,G78) -> Danielle
A79: Vegas, Ms. Julia | E79: Vegas | F79: Ms | G79: Julia | I79: =_xlfn.TEXTJOIN("",TRUE,G79) -> Julia
A80: Cochran, Mr. Joshua | E80: Cochran | F80: Mr | G80: Joshua | I80: =_xlfn.TEXTJOIN("",TRUE,G80) -> Joshua
A81: Holtzapple, Ms. Jennifer | E81: Holtzapple | F81: Ms | G81: Jennifer | I81: =_xlfn.TEXTJOIN("",TRUE,G81) -> Jennifer
A82: Meyer, Ms. Gwen M. | E82: Meyer | F82: Ms | G82: Gwen M | I82: =_xlfn.TEXTJOIN("",TRUE,G82) -> Gwen M
A83: Brickley, Mr. Patrick | E83: Brickley | F83: Mr | G83: Patrick | I83: =_xlfn.TEXTJOIN("",TRUE,G83) -> Patrick
A84: Magee, Ms. Kate | E84: Magee | F84: Ms | G84: Kate | I84: =_xlfn.TEXTJOIN("",TRUE,G84) -> Kate
A85: Thoma, Mr. Kevin | E85: Thoma | F85: Mr | G85: Kevin | I85: =_xlfn.TEXTJOIN("",TRUE,G85) -> Kevin
... A188: Dublin, Mr. Andrew P | E188: Dublin | F188: Mr | G188: Andrew P | I188: =_xlfn.TEXTJOIN("",TRUE,G188) -> Andrew P
A189: Cleland, Mr. George M. V | E189: Cleland | F189: Mr | G189: George M | H189: V | I189: =_xlfn.TEXTJOIN("",TRUE,G189) -> George M
A190: Evans, Ms. Sarah | E190: Evans | F190: Ms | G190: Sarah | I190: =_xlfn.TEXTJOIN("",TRUE,G190) -> Sarah
A191: Boyd, Ms. Lara | E191: Boyd | F191: Ms | G191: Lara | I191: =_xlfn.TEXTJOIN("",TRUE,G191) -> Lara
A192: Roulier, Mr. Sebastien | E192: Roulier | F192: Mr | G192: Sebastien | I192: =_xlfn.TEXTJOIN("",TRUE,G192) -> Sebastien
A193: Mullins, Mr. Padraig | E193: Mullins | F193: Mr | G193: Padraig | I193: =_xlfn.TEXTJOIN("",TRUE,G193) -> Padraig
A194: Hofmann, Ms. Heather | E194: Hofmann | F194: Ms | G194: Heather | I194: =_xlfn.TEXTJOIN("",TRUE,G194) -> Heather
A195: Garcia Garcia, Mr. Jorge | E195: Garcia Garcia | F195: Mr | G195: Jorge | I195: =_xlfn.TEXTJOIN("",TRUE,G195) -> Jorge
A196: Klecker, Mr. Jack R | E196: Klecker | F196: Mr | G196: Jack R | I196: =_xlfn.TEXTJOIN("",TRUE,G196) -> Jack R
A197: Cancre, Mr. Felix | E197: Cancre | F197: Mr | G197: Felix | I197: =_xlfn.TEXTJOIN("",TRUE,G197) -> Felix
A198: Denucci, Mr. Christopher C | E198: Denucci | F198: Mr | G198: Christopher C | I198: =_xlfn.TEXTJOIN("",TRUE,G198) -> Christopher C
A199: Saldana, Mr. Jesse | E199: Saldana | F199: Mr | G199: Jesse | I199: =_xlfn.TEXTJOIN("",TRUE,G199) -> Jesse
A200: Weinberg, Ms. Jill | E200: Weinberg | F200: Ms | G200: Jill | I200: =_xlfn.TEXTJOIN("",TRUE,G200) -> Jill
...

Sheet Data _Transformation
A1: Customer ID | B1: First Name | C1: BMI | D1: HBA1C | E1: Heart Issues | F1: Any Transplants | G1: Cancer history | H1: Number Of Major Surgeries | I1: Smoking Habit | J1: Weight Status | K1: Diabetes Status | L1: DOB | M1: charges | N1: Hospital tier | O1: City tier | P1: State ID | Q1: AGE
A2: Id1 | B2: Kelly | C2: 47.41 | D2: 7.47 | E2: No | F2: No | G2: No | H2: =IF('Medical Examinations'!G2="No major surgery",0,'Medical Examinations'!G2) -> 0 | I2: Smoker | J2: =IF(C2<18.5,"Under weight",IF(C2<25,"Normal weight",IF(C2<30,"Over weight","Obesity"))) -> Obesity | K2: =IF(D2<5.7,"Normal",IF(D2<6.4,"Prediabetes","Diabetes")) -> Diabetes | L2: =DATE('Data cleaning'!P2,MONTH(1&'Data cleaning'!Q2),'Hospitalisation Details'!D2) -> 33794 | M2: 563.84 | N2: tier - 2 | O2: tier - 3 | P2: R1013 | Q2: =INT(YEARFRAC(L2,DATE(2023,6,8))) -> 30 | AB2: bmi | AC2: weight status
A3: Id2 | B3: Matthew D | C3: 30.36 | D3: 5.77 | E3: No | F3: No | G3: No | H3: =IF('Medical Examinations'!G3="No major surgery",0,'Medical Examinations'!G3) -> 0 | I3: Smoker | J3: =IF(C3<18.5,"Under weight",IF(C3<25,"Normal weight",IF(C3<30,"Over weight","Obesity"))) -> Obesity | K3: =IF(D3<5.7,"Normal",IF(D3<6.4,"Prediabetes","Diabetes")) -> Prediabetes | L3: =DATE('Data cleaning'!P3,MONTH(1&'Data cleaning'!Q3),'Hospitalisation Details'!D3) -> 33938 | M3: 570.62 | N3: tier - 2 | O3: tier - 1 | P3: R1013 | Q3: =INT(YEARFRAC(L3,DATE(2023,6,8))) -> 30 | AB3: below 18.5 | AC3: Underweight
A4: Id3 | B4: Phil | C4: 34.485 | D4: 11.87 | E4: Yes | F4: No | G4: No | H4: =IF('Medical Examinations'!G4="No major surgery",0,'Medical Examinations'!G4) -> 2 | I4: Smoker | J4: =IF(C4<18.5,"Under weight",IF(C4<25,"Normal weight",IF(C4<30,"Over weight","Obesity"))) -> Obesity | K4: =IF(D4<5.7,"Normal",IF(D4<6.4,"Prediabetes","Diabetes")) -> Diabetes | L4: =DATE('Data cleaning'!P4,MONTH(1&'Data cleaning'!Q4),'Hospitalisation Details'!D4) -> 34150 | M4: 600 | N4: tier - 2 | O4: tier - 1 | P4: R1013 | Q4: =INT(YEARFRAC(L4,DATE(2023,6,8))) -> 29 | AB4: 18.5-24.9 | AC4: Normal weight
A5: Id4 | B5: Kelsey | C5: 38.095 | D5: 6.05 | E5: No | F5: No | G5: No | H5: =IF('Medical Examinations'!G5="No major surgery",0,'Medical Examinations'!G5) -> 0 | I5: Smoker | J5: =IF(C5<18.5,"Under weight",IF(C5<25,"Normal weight",IF(C5<30,"Over weight","Obesity"))) -> Obesity | K5: =IF(D5<5.7,"Normal",IF(D5<6.4,"Prediabetes","Diabetes")) -> Prediabetes | L5: =DATE('Data cleaning'!P5,MONTH(1&'Data cleaning'!Q5),'Hospitalisation Details'!D5) -> 33860 | M5: 604.54 | N5: tier - 3 | O5: tier - 3 | P5: R1013 | Q5: =INT(YEARFRAC(L5,DATE(2023,6,8))) -> 30 | AB5: 25.0-29.9 | AC5: Overweight
A6: Id5 | B6: Kristyn | C6: 35.53 | D6: 5.45 | E6: No | F6: No | G6: No | H6: =IF('Medical Examinations'!G6="No major surgery",0,'Medical Examinations'!G6) -> 0 | I6: Smoker | J6: =IF(C6<18.5,"Under weight",IF(C6<25,"Normal weight",IF(C6<30,"Over weight","Obesity"))) -> Obesity | K6: =IF(D6<5.7,"Normal",IF(D6<6.4,"Prediabetes","Diabetes")) -> Normal | L6: =DATE('Data cleaning'!P6,MONTH(1&'Data cleaning'!Q6),'Hospitalisation Details'!D6) -> 36003 | M6: 637.26 | N6: tier - 3 | O6: tier - 3 | P6: R1013 | Q6: =INT(YEARFRAC(L6,DATE(2023,6,8))) -> 24 | AB6: 30.0 and above | AC6: Obesity
A7: Id6 | B7: Russell B | C7: 32.8 | D7: 6.59 | E7: No | F7: No | G7: No | H7: =IF('Medical Examinations'!G7="No major surgery",0,'Medical Examinations'!G7) -> 0 | I7: Smoker | J7: =IF(C7<18.5,"Under weight",IF(C7<25,"Normal weight",IF(C7<30,"Over weight","Obesity"))) -> Obesity | K7: =IF(D7<5.7,"Normal",IF(D7<6.4,"Prediabetes","Diabetes")) -> Diabetes | L7: =DATE('Data cleaning'!P7,MONTH(1&'Data cleaning'!Q7),'Hospitalisation Details'!D7) -> 37215 | M7: 646.14 | N7: tier - 3 | O7: tier - 3 | P7: R1012 | Q7: =INT(YEARFRAC(L7,DATE(2023,6,8))) -> 21
A8: Id7 | B8: Scott | C8: 36.4 | D8: 6.07 | E8: No | F8: No | G8: No | H8: =IF('Medical Examinations'!G8="No major surgery",0,'Medical Examinations'!G8) -> 0 | I8: Smoker | J8: =IF(C8<18.5,"Under weight",IF(C8<25,"Normal weight",IF(C8<30,"Over weight","Obesity"))) -> Obesity | K8: =IF(D8<5.7,"Normal",IF(D8<6.4,"Prediabetes","Diabetes")) -> Prediabetes | L8: =DATE('Data cleaning'!P8,MONTH(1&'Data cleaning'!Q8),'Hospitalisation Details'!D8) -> 34121 | M8: 650 | N8: tier - 3 | O8: tier - 3 | P8: R1013 | Q8: =INT(YEARFRAC(L8,DATE(2023,6,8))) -> 30
A9: Id8 | B9: Stephen | C9: 36.96 | D9: 7.93 | E9: No | F9: No | G9: No | H9: =IF('Medical Examinations'!G9="No major surgery",0,'Medical Examinations'!G9) -> 3 | I9: Smoker | J9: =IF(C9<18.5,"Under weight",IF(C9<25,"Normal weight",IF(C9<30,"Over weight","Obesity"))) -> Obesity | K9: =IF(D9<5.7,"Normal",IF(D9<6.4,"Prediabetes","Diabetes")) -> Diabetes | L9: =DATE('Data cleaning'!P9,MONTH(1&'Data cleaning'!Q9),'Hospitalisation Details'!D9) -> 34884 | M9: 650 | N9: tier - 3 | O9: tier - 3 | P9: R1013 | Q9: =INT(YEARFRAC(L9,DATE(2023,6,8))) -> 27
A10: Id9 | B10: Patrick R | C10: 41.14 | D10: 9.58 | E10: Yes | F10: No | G10: Yes | H10: =IF('Medical Examinations'!G10="No major surgery",0,'Medical Examinations'!G10) -> 1 | I10: Smoker | J10: =IF(C10<18.5,"Under weight",IF(C10<25,"Normal weight",IF(C10<30,"Over weight","Obesity"))) -> Obesity | K10: =IF(D10<5.7,"Normal",IF(D10<6.4,"Prediabetes","Diabetes")) -> Diabetes | L10: =DATE('Data cleaning'!P10,MONTH(1&'Data cleaning'!Q10),'Hospitalisation Details'!D10) -> 37589 | M10: 668 | N10: tier - 3 | O10: tier - 2 | P10: R1012 | Q10: =INT(YEARFRAC(L10,DATE(2023,6,8))) -> 20
A11: Id10 | B11: Brooke N | C11: 38.06 | D11: 10.79 | E11: No | F11: No | G11: No | H11: =IF('Medical Examinations'!G11="No major surgery",0,'Medical Examinations'!G11) -> 0 | I11: Smoker | J11: =IF(C11<18.5,"Under weight",IF(C11<25,"Normal weight",IF(C11<30,"Over weight","Obesity"))) -> Obesity | K11: =IF(D11<5.7,"Normal",IF(D11<6.4,"Prediabetes","Diabetes")) -> Diabetes | L11: =DATE('Data cleaning'!P11,MONTH(1&'Data cleaning'!Q11),'Hospitalisation Details'!D11) -> 35743 | M11: 670 | N11: tier - 3 | O11: tier - 3 | P11: R1013 | Q11: =INT(YEARFRAC(L11,DATE(2023,6,8))) -> 25
A12: Id11 | B12: Paola Andrea | C12: 37.7 | D12: 5.96 | E12: Yes | F12: No | G12: No | H12: =IF('Medical Examinations'!G12="No major surgery",0,'Medical Examinations'!G12) -> 2 | I12: Smoker | J12: =IF(C12<18.5,"Under weight",IF(C12<25,"Normal weight",IF(C12<30,"Over weight","Obesity"))) -> Obesity | K12: =IF(D12<5.7,"Normal",IF(D12<6.4,"Prediabetes","Diabetes")) -> Prediabetes | L12: =DATE('Data cleaning'!P12,MONTH(1&'Data cleaning'!Q12),'Hospitalisation Details'!D12) -> 37146 | M12: 687.54 | N12: tier - 3 | O12: tier - 2 | P12: R1013 | Q12: =INT(YEARFRAC(L12,DATE(2023,6,8))) -> 21
A13: Id13 | B13: Wade | C13: 40.92 | D13: 8.41 | E13: No | F13: No | G13: No | H13: =IF('Medical Examinations'!G14="No major surgery",0,'Medical Examinations'!G14) -> 0 | I13: Smoker | J13: =IF(C13<18.5,"Under weight",IF(C13<25,"Normal weight",IF(C13<30,"Over weight","Obesity"))) -> Obesity | K13: =IF(D13<5.7,"Normal",IF(D13<6.4,"Prediabetes","Diabetes")) -> Diabetes | L13: =DATE('Data cleaning'!P14,MONTH(1&'Data cleaning'!Q14),'Hospitalisation Details'!D14) -> 36508 | M13: 722.99 | N13: tier - 3 | O13: tier - 1 | P13: R1013 | Q13: =INT(YEARFRAC(L13,DATE(2023,6,8))) -> 23
A14: Id14 | B14: Franklin | C14: 40.565 | D14: 7.02 | E14: No | F14: No | G14: No | H14: =IF('Medical Examinations'!G15="No major surgery",0,'Medical Examinations'!G15) -> 0 | I14: Smoker | J14: =IF(C14<18.5,"Under weight",IF(C14<25,"Normal weight",IF(C14<30,"Over weight","Obesity"))) -> Obesity | K14: =IF(D14<5.7,"Normal",IF(D14<6.4,"Prediabetes","Diabetes")) -> Diabetes | L14: =DATE('Data cleaning'!P15,MONTH(1&'Data cleaning'!Q15),'Hospitalisation Details'!D15) -> 37518 | M14: 750 | N14: tier - 3 | O14: tier - 1 | P14: R1012 | Q14: =INT(YEARFRAC(L14,DATE(2023,6,8))) -> 20
A15: Id15 | B15: Leilani M | C15: 36.385 | D15: 7.59 | E15: Yes | F15: No | G15: No | H15: =IF('Medical Examinations'!G16="No major surgery",0,'Medical Examinations'!G16) -> 2 | I15: Smoker | J15: =IF(C15<18.5,"Under weight",IF(C15<25,"Normal weight",IF(C15<30,"Over weight","Obesity"))) -> Obesity | K15: =IF(D15<5.7,"Normal",IF(D15<6.4,"Prediabetes","Diabetes")) -> Diabetes | L15: =DATE('Data cleaning'!P16,MONTH(1&'Data cleaning'!Q16),'Hospitalisation Details'!D16) -> 34190 | M15: 760 | N15: tier - 3 | O15: tier - 1 | P15: R1013 | Q15: =INT(YEARFRAC(L15,DATE(2023,6,8))) -> 29
A16: Id16 | B16: Philippe | C16: 39.9 | D16: 11.32 | E16: No | F16: No | G16: No | H16: =IF('Medical Examinations'!G17="No major surgery",0,'Medical Examinations'!G17) -> 0 | I16: Smoker | J16: =IF(C16<18.5,"Under weight",IF(C16<25,"Normal weight",IF(C16<30,"Over weight","Obesity"))) -> Obesity | K16: =IF(D16<5.7,"Normal",IF(D16<6.4,"Prediabetes","Diabetes")) -> Diabetes | L16: =DATE('Data cleaning'!P17,MONTH(1&'Data cleaning'!Q17),'Hospitalisation Details'!D17) -> 35360 | M16: 760 | N16: tier - 3 | O16: tier - 3 | P16: R1013 | Q16: =INT(YEARFRAC(L16,DATE(2023,6,8))) -> 26
A17: Id17 | B17: Jennifer A | C17: 33.8 | D17: 7.67 | E17: No | F17: No | G17: No | H17: =IF('Medical Examinations'!G18="No major surgery",0,'Medical Examinations'!G18) -> 3 | I17: Smoker | J17: =IF(C17<18.5,"Under weight",IF(C17<25,"Normal weight",IF(C17<30,"Over weight","Obesity"))) -> Obesity | K17: =IF(D17<5.7,"Normal",IF(D17<6.4,"Prediabetes","Diabetes")) -> Diabetes | L17: =DATE('Data cleaning'!P18,MONTH(1&'Data cleaning'!Q18),'Hospitalisation Details'!D18) -> 34148 | M17: 770 | N17: tier - 3 | O17: tier - 3 | P17: R1013 | Q17: =INT(YEARFRAC(L17,DATE(2023,6,8))) -> 29
A18: Id19 | B18: Said Sr | C18: 36.955 | D18: 4.72 | E18: Yes | F18: No | G18: No | H18: =IF('Medical Examinations'!G20="No major surgery",0,'Medical Examinations'!G20) -> 1 | I18: Smoker | J18: =IF(C18<18.5,"Under weight",IF(C18<25,"Normal weight",IF(C18<30,"Over weight","Obesity"))) -> Obesity | K18: =IF(D18<5.7,"Normal",IF(D18<6.4,"Prediabetes","Diabetes")) -> Normal | L18: =DATE('Data cleaning'!P20,MONTH(1&'Data cleaning'!Q20),'Hospitalisation Details'!D20) -> 35040 | M18: 773.54 | N18: tier - 3 | O18: tier - 2 | P18: R1013 | Q18: =INT(YEARFRAC(L18,DATE(2023,6,8))) -> 27
A19: Id20 | B19: John | C19: 42.9 | D19: 11.41 | E19: No | F19: No | G19: No | H19: =IF('Medical Examinations'!G21="No major surgery",0,'Medical Examinations'!G21) -> 0 | I19: Smoker | J19: =IF(C19<18.5,"Under weight",IF(C19<25,"Normal weight",IF(C19<30,"Over weight","Obesity"))) -> Obesity | K19: =IF(D19<5.7,"Normal",IF(D19<6.4,"Prediabetes","Diabetes")) -> Diabetes | L19: =DATE('Data cleaning'!P21,MONTH(1&'Data cleaning'!Q21),'Hospitalisation Details'!D21) -> 38267 | M19: 830.52 | N19: tier - 3 | O19: tier - 2 | P19: R1011 | Q19: =INT(YEARFRAC(L19,DATE(2023,6,8))) -> 18
A20: Id21 | B20: Myles | C20: 36.3 | D20: 11.5 | E20: Yes | F20: No | G20: No | H20: =IF('Medical Examinations'!G22="No major surgery",0,'Medical Examinations'!G22) -> 2 | I20: Smoker | J20: =IF(C20<18.5,"Under weight",IF(C20<25,"Normal weight",IF(C20<30,"Over weight","Obesity"))) -> Obesity | K20: =IF(D20<5.7,"Normal",IF(D20<6.4,"Prediabetes","Diabetes")) -> Diabetes | L20: =DATE('Data cleaning'!P22,MONTH(1&'Data cleaning'!Q22),'Hospitalisation Details'!D22) -> 36848 | M20: 865.41 | N20: tier - 3 | O20: tier - 1 | P20: R1013 | Q20: =INT(YEARFRAC(L20,DATE(2023,6,8))) -> 22
A21: Id22 | B21: Madelyn C | C21: 32.2 | D21: 6.22 | E21: Yes | F21: No | G21: No | H21: =IF('Medical Examinations'!G23="No major surgery",0,'Medical Examinations'!G23) -> 2 | I21: Smoker | J21: =IF(C21<18.5,"Under weight",IF(C21<25,"Normal weight",IF(C21<30,"Over weight","Obesity"))) -> Obesity | K21: =IF(D21<5.7,"Normal",IF(D21<6.4,"Prediabetes","Diabetes")) -> Prediabetes | L21: =DATE('Data cleaning'!P23,MONTH(1&'Data cleaning'!Q23),'Hospitalisation Details'!D23) -> 34300 | M21: 896.21 | N21: tier - 3 | O21: tier - 1 | P21: R1013 | Q21: =INT(YEARFRAC(L21,DATE(2023,6,8))) -> 29
A22: Id23 | B22: Nicole | C22: 31.3 | D22: 11.38 | E22: No | F22: No | G22: No | H22: =IF('Medical Examinations'!G24="No major surgery",0,'Medical Examinations'!G24) -> 3 | I22: Smoker | J22: =IF(C22<18.5,"Under weight",IF(C22<25,"Normal weight",IF(C22<30,"Over weight","Obesity"))) -> Obesity | K22: =IF(D22<5.7,"Normal",IF(D22<6.4,"Prediabetes","Diabetes")) -> Diabetes | L22: =DATE('Data cleaning'!P24,MONTH(1&'Data cleaning'!Q24),'Hospitalisation Details'!D24) -> 34637 | M22: 915.07 | N22: tier - 3 | O22: tier - 1 | P22: R1013 | Q22: =INT(YEARFRAC(L22,DATE(2023,6,8))) -> 28
A23: Id24 | B23: Eric A | C23: 41.8 | D23: 7.89 | E23: Yes | F23: No | G23: No | H23: =IF('Medical Examinations'!G25="No major surgery",0,'Medical Examinations'!G25) -> 2 | I23: Smoker | J23: =IF(C23<18.5,"Under weight",IF(C23<25,"Normal weight",IF(C23<30,"Over weight","Obesity"))) -> Obesity | K23: =IF(D23<5.7,"Normal",IF(D23<6.4,"Prediabetes","Diabetes")) -> Diabetes | L23: =DATE('Data cleaning'!P25,MONTH(1&'Data cleaning'!Q25),'Hospitalisation Details'!D25) -> 35000 | M23: 928.59 | N23: tier - 3 | O23: tier - 1 | P23: R1013 | Q23: =INT(YEARFRAC(L23,DATE(2023,6,8))) -> 27
A24: Id25 | B24: Emiliano I | C24: 35.09 | D24: 4.38 | E24: Yes | F24: No | G24: No | H24: =IF('Medical Examinations'!G26="No major surgery",0,'Medical Examinations'!G26) -> 2 | I24: Smoker | J24: =IF(C24<18.5,"Under weight",IF(C24<25,"Normal weight",IF(C24<30,"Over weight","Obesity"))) -> Obesity | K24: =IF(D24<5.7,"Normal",IF(D24<6.4,"Prediabetes","Diabetes")) -> Normal | L24: =DATE('Data cleaning'!P26,MONTH(1&'Data cleaning'!Q26),'Hospitalisation Details'!D26) -> 37122 | M24: 964.71 | N24: tier - 3 | O24: tier - 2 | P24: R1013 | Q24: =INT(YEARFRAC(L24,DATE(2023,6,8))) -> 21
A25: Id26 | B25: Adam | C25: 33.88 | D25: 7.01 | E25: No | F25: No | G25: No | H25: =IF('Medical Examinations'!G27="No major surgery",0,'Medical Examinations'!G27) -> 3 | I25: Smoker | J25: =IF(C25<18.5,"Under weight",IF(C25<25,"Normal weight",IF(C25<30,"Over weight","Obesity"))) -> Obesity | K25: =IF(D25<5.7,"Normal",IF(D25<6.4,"Prediabetes","Diabetes")) -> Diabetes | L25: =DATE('Data cleaning'!P27,MONTH(1&'Data cleaning'!Q27),'Hospitalisation Details'!D27) -> 34660 | M25: 1006.65 | N25: tier - 3 | O25: tier - 2 | P25: R1013 | Q25: =INT(YEARFRAC(L25,DATE(2023,6,8))) -> 28
A26: Id27 | B26: Zach | C26: 30.875 | D26: 11.88 | E26: No | F26: No | G26: No | H26: =IF('Medical Examinations'!G28="No major surgery",0,'Medical Examinations'!G28) -> 0 | I26: Smoker | J26: =IF(C26<18.5,"Under weight",IF(C26<25,"Normal weight",IF(C26<30,"Over weight","Obesity"))) -> Obesity | K26: =IF(D26<5.7,"Normal",IF(D26<6.4,"Prediabetes","Diabetes")) -> Diabetes | L26: =DATE('Data cleaning'!P28,MONTH(1&'Data cleaning'!Q28),'Hospitalisation Details'!D28) -> 36808 | M26: 1012 | N26: tier - 3 | O26: tier - 2 | P26: R1013 | Q26: =INT(YEARFRAC(L26,DATE(2023,6,8))) -> 22
A27: Id28 | B27: Stephanie W | C27: 36.86 | D27: 5.19 | E27: Yes | F27: No | G27: Yes | H27: =IF('Medical Examinations'!G29="No major surgery",0,'Medical Examinations'!G29) -> 1 | I27: Smoker | J27: =IF(C27<18.5,"Under weight",IF(C27<25,"Normal weight",IF(C27<30,"Over weight","Obesity"))) -> Obesity | K27: =IF(D27<5.7,"Normal",IF(D27<6.4,"Prediabetes","Diabetes")) -> Normal | L27: =DATE('Data cleaning'!P29,MONTH(1&'Data cleaning'!Q29),'Hospitalisation Details'!D29) -> 36377 | M27: 1019 | N27: tier - 3 | O27: tier - 2 | P27: R1013 | Q27: =INT(YEARFRAC(L27,DATE(2023,6,8))) -> 23
A28: Id29 | B28: Stephen | C28: 35.86 | D28: 6.74 | E28: Yes | F28: No | G28: No | H28: =IF('Medical Examinations'!G30="No major surgery",0,'Medical Examinations'!G30) -> 2 | I28: Smoker | J28: =IF(C28<18.5,"Under weight",IF(C28<25,"Normal weight",IF(C28<30,"Over weight","Obesity"))) -> Obesity | K28: =IF(D28<5.7,"Normal",IF(D28<6.4,"Prediabetes","Diabetes")) -> Diabetes | L28: =DATE('Data cleaning'!P30,MONTH(1&'Data cleaning'!Q30),'Hospitalisation Details'!D30) -> 34977 | M28: 1033.74 | N28: tier - 3 | O28: tier - 1 | P28: R1013 | Q28: =INT(YEARFRAC(L28,DATE(2023,6,8))) -> 27
A29: Id30 | B29: Natalie | C29: 37.05 | D29: 8.44 | E29: No | F29: No | G29: No | H29: =IF('Medical Examinations'!G31="No major surgery",0,'Medical Examinations'!G31) -> 0 | I29: Smoker | J29: =IF(C29<18.5,"Under weight",IF(C29<25,"Normal weight",IF(C29<30,"Over weight","Obesity"))) -> Obesity | K29: =IF(D29<5.7,"Normal",IF(D29<6.4,"Prediabetes","Diabetes")) -> Diabetes | L29: =DATE('Data cleaning'!P31,MONTH(1&'Data cleaning'!Q31),'Hospitalisation Details'!D31) -> 34655 | M29: 1044 | N29: tier - 3 | O29: tier - 2 | P29: R1013 | Q29: =INT(YEARFRAC(L29,DATE(2023,6,8))) -> 28
... A543: Id544 | B543: Brooke M | C543: 32.23 | D543: 4.65 | E543: Yes | F543: No | G543: Yes | H543: =IF('Medical Examinations'!G545="No major surgery",0,'Medical Examinations'!G545) -> 1 | I543: Nonsmoker | J543: =IF(C543<18.5,"Under weight",IF(C543<25,"Normal weight",IF(C543<30,"Over weight","Obesity"))) -> Obesity | K543: =IF(D543<5.7,"Normal",IF(D543<6.4,"Prediabetes","Diabetes")) -> Normal | L543: =DATE('Data cleaning'!P545,MONTH(1&'Data cleaning'!Q545),'Hospitalisation Details'!D545) -> 29770 | M543: 4827.1 | N543: tier - 2 | O543: tier - 1 | P543: R1013 | Q543: =INT(YEARFRAC(L543,DATE(2023,6,8))) -> 41
A544: Id546 | B544: Zachary | C544: 29.735 | D544: 4.53 | E544: No | F544: No | G544: Yes | H544: =IF('Medical Examinations'!G547="No major surgery",0,'Medical Examinations'!G547) -> 1 | I544: Nonsmoker | J544: =IF(C544<18.5,"Under weight",IF(C544<25,"Normal weight",IF(C544<30,"Over weight","Obesity"))) -> Over weight | K544: =IF(D544<5.7,"Normal",IF(D544<6.4,"Prediabetes","Diabetes")) -> Normal | L544: =DATE('Data cleaning'!P547,MONTH(1&'Data cleaning'!Q547),'Hospitalisation Details'!D547) -> 37434 | M544: 4830.63 | N544: tier - 2 | O544: tier - 1 | P544: R1011 | Q544: =INT(YEARFRAC(L544,DATE(2023,6,8))) -> 20
A545: Id547 | B545: Johannah | C545: 28.31 | D545: 6.35 | E545: No | F545: No | G545: No | H545: =IF('Medical Examinations'!G548="No major surgery",0,'Medical Examinations'!G548) -> 0 | I545: Smoker | J545: =IF(C545<18.5,"Under weight",IF(C545<25,"Normal weight",IF(C545<30,"Over weight","Obesity"))) -> Over weight | K545: =IF(D545<5.7,"Normal",IF(D545<6.4,"Prediabetes","Diabetes")) -> Prediabetes | L545: =DATE('Data cleaning'!P548,MONTH(1&'Data cleaning'!Q548),'Hospitalisation Details'!D548) -> 36871 | M545: 4835.43 | N545: tier - 2 | O545: tier - 2 | P545: R1021 | Q545: =INT(YEARFRAC(L545,DATE(2023,6,8))) -> 22
A546: Id548 | B546: Ryan A | C546: 46.62 | D546: 8.51 | E546: No | F546: No | G546: No | H546: =IF('Medical Examinations'!G549="No major surgery",0,'Medical Examinations'!G549) -> 0 | I546: Nonsmoker | J546: =IF(C546<18.5,"Under weight",IF(C546<25,"Normal weight",IF(C546<30,"Over weight","Obesity"))) -> Obesity | K546: =IF(D546<5.7,"Normal",IF(D546<6.4,"Prediabetes","Diabetes")) -> Diabetes | L546: =DATE('Data cleaning'!P549,MONTH(1&'Data cleaning'!Q549),'Hospitalisation Details'!D549) -> 33857 | M546: 4837.58 | N546: tier - 3 | O546: tier - 2 | P546: R1013 | Q546: =INT(YEARFRAC(L546,DATE(2023,6,8))) -> 30
A547: Id549 | B547: Andres Sr | C547: 51.75 | D547: 8.59 | E547: Yes | F547: No | G547: No | H547: =IF('Medical Examinations'!G550="No major surgery",0,'Medical Examinations'!G550) -> 1 | I547: Nonsmoker | J547: =IF(C547<18.5,"Under weight",IF(C547<25,"Normal weight",IF(C547<30,"Over weight","Obesity"))) -> Obesity | K547: =IF(D547<5.7,"Normal",IF(D547<6.4,"Prediabetes","Diabetes")) -> Diabetes | L547: =DATE('Data cleaning'!P550,MONTH(1&'Data cleaning'!Q550),'Hospitalisation Details'!D550) -> 30970 | M547: 4839.18 | N547: tier - 2 | O547: tier - 1 | P547: R1012 | Q547: =INT(YEARFRAC(L547,DATE(2023,6,8))) -> 38
A548: Id550 | B548: Bryan | C548: 25.7 | D548: 4.13 | E548: Yes | F548: No | G548: No | H548: =IF('Medical Examinations'!G551="No major surgery",0,'Medical Examinations'!G551) -> 0 | I548: Smoker | J548: =IF(C548<18.5,"Under weight",IF(C548<25,"Normal weight",IF(C548<30,"Over weight","Obesity"))) -> Over weight | K548: =IF(D548<5.7,"Normal",IF(D548<6.4,"Prediabetes","Diabetes")) -> Normal | L548: =DATE('Data cleaning'!P551,MONTH(1&'Data cleaning'!Q551),'Hospitalisation Details'!D551) -> 34971 | M548: 4840.95 | N548: tier - 2 | O548: tier - 1 | P548: R1021 | Q548: =INT(YEARFRAC(L548,DATE(2023,6,8))) -> 27
A549: Id551 | B549: Lizette | C549: 31.79 | D549: 4.55 | E549: No | F549: No | G549: No | H549: =IF('Medical Examinations'!G552="No major surgery",0,'Medical Examinations'!G552) -> 0 | I549: Nonsmoker | J549: =IF(C549<18.5,"Under weight",IF(C549<25,"Normal weight",IF(C549<30,"Over weight","Obesity"))) -> Obesity | K549: =IF(D549<5.7,"Normal",IF(D549<6.4,"Prediabetes","Diabetes")) -> Normal | L549: =DATE('Data cleaning'!P552,MONTH(1&'Data cleaning'!Q552),'Hospitalisation Details'!D552) -> 29202 | M549: 4843.79 | N549: tier - 2 | O549: tier - 3 | P549: R1013 | Q549: =INT(YEARFRAC(L549,DATE(2023,6,8))) -> 43
A550: Id552 | B550: Don | C550: 24.795 | D550: 4.52 | E550: No | F550: No | G550: No | H550: =IF('Medical Examinations'!G553="No major surgery",0,'Medical Examinations'!G553) -> 0 | I550: Smoker | J550: =IF(C550<18.5,"Under weight",IF(C550<25,"Normal weight",IF(C550<30,"Over weight","Obesity"))) -> Normal weight | K550: =IF(D550<5.7,"Normal",IF(D550<6.4,"Prediabetes","Diabetes")) -> Normal | L550: =DATE('Data cleaning'!P553,MONTH(1&'Data cleaning'!Q553),'Hospitalisation Details'!D553) -> 27283 | M550: 4844.67 | N550: tier - 2 | O550: tier - 2 | P550: R1013 | Q550: =INT(YEARFRAC(L550,DATE(2023,6,8))) -> 48
A551: Id553 | B551: Jeb | C551: 53.98 | D551: 5.07 | E551: No | F551: No | G551: Yes | H551: =IF('Medical Examinations'!G554="No major surgery",0,'Medical Examinations'!G554) -> 1 | I551: Nonsmoker | J551: =IF(C551<18.5,"Under weight",IF(C551<25,"Normal weight",IF(C551<30,"Over weight","Obesity"))) -> Obesity | K551: =IF(D551<5.7,"Normal",IF(D551<6.4,"Prediabetes","Diabetes")) -> Normal | L551: =DATE('Data cleaning'!P554,MONTH(1&'Data cleaning'!Q554),'Hospitalisation Details'!D554) -> 37049 | M551: 4846.53 | N551: tier - 2 | O551: tier - 3 | P551: R1021 | Q551: =INT(YEARFRAC(L551,DATE(2023,6,8))) -> 22
A552: Id554 | B552: Amy R | C552: 41.325 | D552: 4.04 | E552: Yes | F552: No | G552: Yes | H552: =IF('Medical Examinations'!G555="No major surgery",0,'Medical Examinations'!G555) -> 1 | I552: Nonsmoker | J552: =IF(C552<18.5,"Under weight",IF(C552<25,"Normal weight",IF(C552<30,"Over weight","Obesity"))) -> Obesity | K552: =IF(D552<5.7,"Normal",IF(D552<6.4,"Prediabetes","Diabetes")) -> Normal | L552: =DATE('Data cleaning'!P555,MONTH(1&'Data cleaning'!Q555),'Hospitalisation Details'!D555) -> 35060 | M552: 4846.92 | N552: tier - 2 | O552: tier - 3 | P552: R1017 | Q552: =INT(YEARFRAC(L552,DATE(2023,6,8))) -> 27
A553: Id555 | B553: Brian | C553: 51.65 | D553: 5.3 | E553: Yes | F553: No | G553: No | H553: =IF('Medical Examinations'!G556="No major surgery",0,'Medical Examinations'!G556) -> 0 | I553: Nonsmoker | J553: =IF(C553<18.5,"Under weight",IF(C553<25,"Normal weight",IF(C553<30,"Over weight","Obesity"))) -> Obesity | K553: =IF(D553<5.7,"Normal",IF(D553<6.4,"Prediabetes","Diabetes")) -> Normal | L553: =DATE('Data cleaning'!P556,MONTH(1&'Data cleaning'!Q556),'Hospitalisation Details'!D556) -> 32752 | M553: 4859.89 | N553: tier - 2 | O553: tier - 3 | P553: R1011 | Q553: =INT(YEARFRAC(L553,DATE(2023,6,8))) -> 33
...

Sheet Analysis using pie
E2: ANALYSIS USING PIE
C6: Row Labels | D6: Count of Cancer history | I6: Row Labels | J6: Sum of Number Of Major Surgeries | K6: Average of HBA1C
C7: Nonsmoker | D7: 1843 | I7: No | J7: 1415 | K7: 6.6640393
C8: Smoker | D8: 486 | I8: yes | J8: 161 | K8: 5.1892308
C9: Grand Total | D9: 2329 | I9: Grand Total | J9: 1576 | K9: 6.5734865

Sheet Analysis using coloumn
C7: Row Labels | D7: Sum of charges
C8: Normal weight | D8: 7548637.4
C9: Diabetes | D9: 1600454.1
C10: Normal | D10: 4432578.6
C11: Prediabetes | D11: 1515604.7
C12: Obesity | D12: 12794625
C13: Diabetes | D13: 3135976
C14: Normal | D14: 6922656.9
C15: Prediabetes | D15: 2735992.5
C16: Over weight | D16: 6802389.4
C17: Diabetes | D17: 1518140.5
C18: Normal | D18: 3623672.9
C19: Prediabetes | D19: 1660576
... C24: Grand Total | D24: 31261668
C28: Row Labels | D28: Average of charges
C29: R1011 | D29: 32861.436
C30: R1012 | D30: 24775.306
C31: R1013 | D31: 30888.292
C32: R1014 | D32: 13891.86
C33: R1015 | D33: 21523.52
C34: R1016 | D34: 39868.616
C35: R1017 | D35: 34070.596
C36: R1018 | D36: 33475.82
C37: R1019 | D37: 27621.61
C38: R1023 | D38: 18261.757
C39: R1024 | D39: 30744.581
C40: R1026 | D40: 18709.798
C41: Grand Total | D41: 29659.936

Sheet Analysis using line
E3: ANALYSIS USING LINE
C7: Row Labels | D7: Average of charges
C8: 18 | D8: 6842.7445
C9: 19 | D9: 9677.1869
C10: 20 | D10: 7411.4483
C11: 21 | D11: 5214.5293
C12: 22 | D12: 9775.856
C13: 23 | D13: 11134.437
C14: 24 | D14: 9765.5713
C15: 25 | D15: 9184.887
C16: 26 | D16: 6040.3591
C17: 27 | D17: 11986.609
C18: 28 | D18: 8456.6384
C19: 29 | D19: 9914.8
... C55: 65 | D55: 29330.98
C56: Grand Total | D56: 13422.786
C62: Row Labels | D62: Average of BMI | E62: Average of HBA1C
C63: 18 | D63: 34.4925 | E63: 6.9319792
C64: 19 | D64: 34.060291 | E64: 6.5430233
C65: 20 | D65: 33.460862 | E65: 6.5805172
C66: 21 | D66: 31.293721 | E66: 6.9016279
C67: 22 | D67: 33.706154 | E67: 6.3892308
C68: 23 | D68: 33.3604 | E68: 6.0776
C69: 24 | D69: 32.126196 | E69: 6.4032609
C70: 25 | D70: 32.628421 | E70: 7.3436842
C71: 26 | D71: 31.237674 | E71: 6.9174419
C72: 27 | D72: 31.1156 | E72: 6.0396
C73: 28 | D73: 31.679909 | E73: 6.7907273
C74: 29 | D74: 31.924623 | E74: 6.9113208
... C110: 65 | D110: 22.61 | E110: 4.25
C111: Grand Total | D111: 30.965715 | E111: 6.5734865

Sheet Dashboard
A1: HEALTHCARE ANALYSIS

Sheet Healthcare
A1: Customer ID | B1: First Name | C1: BMI | D1: HBA1C | E1: Heart Issues | F1: Any Transplants | G1: Cancer history | H1: Number Of Major Surgeries | I1: Smoking Habit | J1: Weight Status | K1: Diabetes Status | L1: DOB | M1: charges | N1: Hospital tier | O1: City tier | P1: State ID | Q1: AGE
A2: Id1 | B2: =VLOOKUP(A2,'Data _Transformation'!A1:Q2330,2,FALSE) -> Kelly | C2: =VLOOKUP(A2,'Data _Transformation'!A1:Q2330,3,FALSE) -> 47.41 | D2: =VLOOKUP(A2,'Data _Transformation'!A1:Q2330,4,FALSE) -> 7.47 | E2: =VLOOKUP(A2,'Data _Transformation'!A1:Q2330,5,FALSE) -> No | F2: =VLOOKUP(A2,'Data _Transformation'!A1:Q2330,6,FALSE) -> No | G2: =VLOOKUP(A2,'Data _Transformation'!A1:Q2330,7,FALSE) -> No | H2: =VLOOKUP(A2,'Data _Transformation'!A1:Q2330,8,FALSE) -> 0 | I2: =VLOOKUP(A2,'Data _Transformation'!A1:Q2330,9,FALSE) -> Smoker | J2: =VLOOKUP(A2,'Data _Transformation'!A1:Q2330,10,FALSE) -> Obesity | K2: =VLOOKUP(A2,'Data _Transformation'!A1:Q2330,11,FALSE) -> Diabetes | L2: =VLOOKUP(A2,'Data _Transformation'!A1:Q2330,12,FALSE) -> 33794 | M2: =VLOOKUP(A2,'Data _Transformation'!A1:Q2330,13,FALSE) -> 563.84 | N2: =VLOOKUP(A2,'Data _Transformation'!A1:Q2330,14,FALSE) -> tier - 2 | O2: =VLOOKUP(A2,'Data _Transformation'!A1:Q2330,15,FALSE) -> tier - 3 | P2: =VLOOKUP(A2,'Data _Transformation'!A1:Q2330,16,0) -> R1013 | Q2: =VLOOKUP(A2,'Data _Transformation'!A1:Q2330,17,0) -> 30
A3: Id2 | B3: =VLOOKUP(A3,'Data _Transformation'!A2:Q2331,2,FALSE) -> Matthew D | C3: =VLOOKUP(A3,'Data _Transformation'!A2:Q2331,3,FALSE) -> 30.36 | D3: =VLOOKUP(A3,'Data _Transformation'!A2:Q2331,4,FALSE) -> 5.77 | E3: =VLOOKUP(A3,'Data _Transformation'!A2:Q2331,5,FALSE) -> No | F3: =VLOOKUP(A3,'Data _Transformation'!A2:Q2331,6,FALSE) -> No | G3: =VLOOKUP(A3,'Data _Transformation'!A2:Q2331,7,FALSE) -> No | H3: =VLOOKUP(A3,'Data _Transformation'!A2:Q2331,8,FALSE) -> 0 | I3: =VLOOKUP(A3,'Data _Transformation'!A2:Q2331,9,FALSE) -> Smoker | J3: =VLOOKUP(A3,'Data _Transformation'!A2:Q2331,10,FALSE) -> Obesity | K3: =VLOOKUP(A3,'Data _Transformation'!A2:Q2331,11,FALSE) -> Prediabetes | L3: =VLOOKUP(A3,'Data _Transformation'!A2:Q2331,12,FALSE) -> 33938 | M3: =VLOOKUP(A3,'Data _Transformation'!A2:Q2331,13,FALSE) -> 570.62 | N3: =VLOOKUP(A3,'Data _Transformation'!A2:Q2331,14,FALSE) -> tier - 2 | O3: =VLOOKUP(A3,'Data _Transformation'!A2:Q2331,15,FALSE) -> tier - 1 | P3: =VLOOKUP(A3,'Data _Transformation'!A2:Q2331,16,0) -> R1013 | Q3: =VLOOKUP(A3,'Data _Transformation'!A2:Q2331,17,0) -> 30
A4: Id3 | B4: =VLOOKUP(A4,'Data _Transformation'!A3:Q2332,2,FALSE) -> Phil | C4: =VLOOKUP(A4,'Data _Transformation'!A3:Q2332,3,FALSE) -> 34.485 | D4: =VLOOKUP(A4,'Data _Transformation'!A3:Q2332,4,FALSE) -> 11.87 | E4: =VLOOKUP(A4,'Data _Transformation'!A3:Q2332,5,FALSE) -> Yes | F4: =VLOOKUP(A4,'Data _Transformation'!A3:Q2332,6,FALSE) -> No | G4: =VLOOKUP(A4,'Data _Transformation'!A3:Q2332,7,FALSE) -> No | H4: =VLOOKUP(A4,'Data _Transformation'!A3:Q2332,8,FALSE) -> 2 | I4: =VLOOKUP(A4,'Data _Transformation'!A3:Q2332,9,FALSE) -> Smoker | J4: =VLOOKUP(A4,'Data _Transformation'!A3:Q2332,10,FALSE) -> Obesity | K4: =VLOOKUP(A4,'Data _Transformation'!A3:Q2332,11,FALSE) -> Diabetes | L4: =VLOOKUP(A4,'Data _Transformation'!A3:Q2332,12,FALSE) -> 34150 | M4: =VLOOKUP(A4,'Data _Transformation'!A3:Q2332,13,FALSE) -> 600 | N4: =VLOOKUP(A4,'Data _Transformation'!A3:Q2332,14,FALSE) -> tier - 2 | O4: =VLOOKUP(A4,'Data _Transformation'!A3:Q2332,15,FALSE) -> tier - 1 | P4: =VLOOKUP(A4,'Data _Transformation'!A3:Q2332,16,0) -> R1013 | Q4: =VLOOKUP(A4,'Data _Transformation'!A3:Q2332,17,0) -> 29
A5: Id4 | B5: =VLOOKUP(A5,'Data _Transformation'!A4:Q2333,2,FALSE) -> Kelsey | C5: =VLOOKUP(A5,'Data _Transformation'!A4:Q2333,3,FALSE) -> 38.095 | D5: =VLOOKUP(A5,'Data _Transformation'!A4:Q2333,4,FALSE) -> 6.05 | E5: =VLOOKUP(A5,'Data _Transformation'!A4:Q2333,5,FALSE) -> No | F5: =VLOOKUP(A5,'Data _Transformation'!A4:Q2333,6,FALSE) -> No | G5: =VLOOKUP(A5,'Data _Transformation'!A4:Q2333,7,FALSE) -> No | H5: =VLOOKUP(A5,'Data _Transformation'!A4:Q2333,8,FALSE) -> 0 | I5: =VLOOKUP(A5,'Data _Transformation'!A4:Q2333,9,FALSE) -> Smoker | J5: =VLOOKUP(A5,'Data _Transformation'!A4:Q2333,10,FALSE) -> Obesity | K5: =VLOOKUP(A5,'Data _Transformation'!A4:Q2333,11,FALSE) -> Prediabetes | L5: =VLOOKUP(A5,'Data _Transformation'!A4:Q2333,12,FALSE) -> 33860 | M5: =VLOOKUP(A5,'Data _Transformation'!A4:Q2333,13,FALSE) -> 604.54 | N5: =VLOOKUP(A5,'Data _Transformation'!A4:Q2333,14,FALSE) -> tier - 3 | O5: =VLOOKUP(A5,'Data _Transformation'!A4:Q2333,15,FALSE) -> tier - 3 | P5: =VLOOKUP(A5,'Data _Transformation'!A4:Q2333,16,0) -> R1013 | Q5: =VLOOKUP(A5,'Data _Transformation'!A4:Q2333,17,0) -> 30
A6: Id5 | B6: =VLOOKUP(A6,'Data _Transformation'!A5:Q2334,2,FALSE) -> Kristyn | C6: =VLOOKUP(A6,'Data _Transformation'!A5:Q2334,3,FALSE) -> 35.53 | D6: =VLOOKUP(A6,'Data _Transformation'!A5:Q2334,4,FALSE) -> 5.45 | E6: =VLOOKUP(A6,'Data _Transformation'!A5:Q2334,5,FALSE) -> No | F6: =VLOOKUP(A6,'Data _Transformation'!A5:Q2334,6,FALSE) -> No | G6: =VLOOKUP(A6,'Data _Transformation'!A5:Q2334,7,FALSE) -> No | H6: =VLOOKUP(A6,'Data _Transformation'!A5:Q2334,8,FALSE) -> 0 | I6: =VLOOKUP(A6,'Data _Transformation'!A5:Q2334,9,FALSE) -> Smoker | J6: =VLOOKUP(A6,'Data _Transformation'!A5:Q2334,10,FALSE) -> Obesity | K6: =VLOOKUP(A6,'Data _Transformation'!A5:Q2334,11,FALSE) -> Normal | L6: =VLOOKUP(A6,'Data _Transformation'!A5:Q2334,12,FALSE) -> 36003 | M6: =VLOOKUP(A6,'Data _Transformation'!A5:Q2334,13,FALSE) -> 637.26 | N6: =VLOOKUP(A6,'Data _Transformation'!A5:Q2334,14,FALSE) -> tier - 3 | O6: =VLOOKUP(A6,'Data _Transformation'!A5:Q2334,15,FALSE) -> tier - 3 | P6: =VLOOKUP(A6,'Data _Transformation'!A5:Q2334,16,0) -> R1013 | Q6: =VLOOKUP(A6,'Data _Transformation'!A5:Q2334,17,0) -> 24
A7: Id6 | B7: =VLOOKUP(A7,'Data _Transformation'!A6:Q2335,2,FALSE) -> Russell B | C7: =VLOOKUP(A7,'Data _Transformation'!A6:Q2335,3,FALSE) -> 32.8 | D7: =VLOOKUP(A7,'Data _Transformation'!A6:Q2335,4,FALSE) -> 6.59 | E7: =VLOOKUP(A7,'Data _Transformation'!A6:Q2335,5,FALSE) -> No | F7: =VLOOKUP(A7,'Data _Transformation'!A6:Q2335,6,FALSE) -> No | G7: =VLOOKUP(A7,'Data _Transformation'!A6:Q2335,7,FALSE) -> No | H7: =VLOOKUP(A7,'Data _Transformation'!A6:Q2335,8,FALSE) -> 0 | I7: =VLOOKUP(A7,'Data _Transformation'!A6:Q2335,9,FALSE) -> Smoker | J7: =VLOOKUP(A7,'Data _Transformation'!A6:Q2335,10,FALSE) -> Obesity | K7: =VLOOKUP(A7,'Data _Transformation'!A6:Q2335,11,FALSE) -> Diabetes | L7: =VLOOKUP(A7,'Data _Transformation'!A6:Q2335,12,FALSE) -> 37215 | M7: =VLOOKUP(A7,'Data _Transformation'!A6:Q2335,13,FALSE) -> 646.14 | N7: =VLOOKUP(A7,'Data _Transformation'!A6:Q2335,14,FALSE) -> tier - 3 | O7: =VLOOKUP(A7,'Data _Transformation'!A6:Q2335,15,FALSE) -> tier - 3 | P7: =VLOOKUP(A7,'Data _Transformation'!A6:Q2335,16,0) -> R1012 | Q7: =VLOOKUP(A7,'Data _Transformation'!A6:Q2335,17,0) -> 21
A8: Id7 | B8: =VLOOKUP(A8,'Data _Transformation'!A7:Q2336,2,FALSE) -> Scott | C8: =VLOOKUP(A8,'Data _Transformation'!A7:Q2336,3,FALSE) -> 36.4 | D8: =VLOOKUP(A8,'Data _Transformation'!A7:Q2336,4,FALSE) -> 6.07 | E8: =VLOOKUP(A8,'Data _Transformation'!A7:Q2336,5,FALSE) -> No | F8: =VLOOKUP(A8,'Data _Transformation'!A7:Q2336,6,FALSE) -> No | G8: =VLOOKUP(A8,'Data _Transformation'!A7:Q2336,7,FALSE) -> No | H8: =VLOOKUP(A8,'Data _Transformation'!A7:Q2336,8,FALSE) -> 0 | I8: =VLOOKUP(A8,'Data _Transformation'!A7:Q2336,9,FALSE) -> Smoker | J8: =VLOOKUP(A8,'Data _Transformation'!A7:Q2336,10,FALSE) -> Obesity | K8: =VLOOKUP(A8,'Data _Transformation'!A7:Q2336,11,FALSE) -> Prediabetes | L8: =VLOOKUP(A8,'Data _Transformation'!A7:Q2336,12,FALSE) -> 34121 | M8: =VLOOKUP(A8,'Data _Transformation'!A7:Q2336,13,FALSE) -> 650 | N8: =VLOOKUP(A8,'Data _Transformation'!A7:Q2336,14,FALSE) -> tier - 3 | O8: =VLOOKUP(A8,'Data _Transformation'!A7:Q2336,15,FALSE) -> tier - 3 | P8: =VLOOKUP(A8,'Data _Transformation'!A7:Q2336,16,0) -> R1013 | Q8: =VLOOKUP(A8,'Data _Transformation'!A7:Q2336,17,0) -> 30
A9: Id8 | B9: =VLOOKUP(A9,'Data _Transformation'!A8:Q2337,2,FALSE) -> Stephen | C9: =VLOOKUP(A9,'Data _Transformation'!A8:Q2337,3,FALSE) -> 36.96 | D9: =VLOOKUP(A9,'Data _Transformation'!A8:Q2337,4,FALSE) -> 7.93 | E9: =VLOOKUP(A9,'Data _Transformation'!A8:Q2337,5,FALSE) -> No | F9: =VLOOKUP(A9,'Data _Transformation'!A8:Q2337,6,FALSE) -> No | G9: =VLOOKUP(A9,'Data _Transformation'!A8:Q2337,7,FALSE) -> No | H9: =VLOOKUP(A9,'Data _Transformation'!A8:Q2337,8,FALSE) -> 3 | I9: =VLOOKUP(A9,'Data _Transformation'!A8:Q2337,9,FALSE) -> Smoker | J9: =VLOOKUP(A9,'Data _Transformation'!A8:Q2337,10,FALSE) -> Obesity | K9: =VLOOKUP(A9,'Data _Transformation'!A8:Q2337,11,FALSE) -> Diabetes | L9: =VLOOKUP(A9,'Data _Transformation'!A8:Q2337,12,FALSE) -> 34884 | M9: =VLOOKUP(A9,'Data _Transformation'!A8:Q2337,13,FALSE) -> 650 | N9: =VLOOKUP(A9,'Data _Transformation'!A8:Q2337,14,FALSE) -> tier - 3 | O9: =VLOOKUP(A9,'Data _Transformation'!A8:Q2337,15,FALSE) -> tier - 3 | P9: =VLOOKUP(A9,'Data _Transformation'!A8:Q2337,16,0) -> R1013 | Q9: =VLOOKUP(A9,'Data _Transformation'!A8:Q2337,17,0) -> 27
A10: Id9 | B10: =VLOOKUP(A10,'Data _Transformation'!A9:Q2338,2,FALSE) -> Patrick R | C10: =VLOOKUP(A10,'Data _Transformation'!A9:Q2338,3,FALSE) -> 41.14 | D10: =VLOOKUP(A10,'Data _Transformation'!A9:Q2338,4,FALSE) -> 9.58 | E10: =VLOOKUP(A10,'Data _Transformation'!A9:Q2338,5,FALSE) -> Yes | F10: =VLOOKUP(A10,'Data _Transformation'!A9:Q2338,6,FALSE) -> No | G10: =VLOOKUP(A10,'Data _Transformation'!A9:Q2338,7,FALSE) -> Yes | H10: =VLOOKUP(A10,'Data _Transformation'!A9:Q2338,8,FALSE) -> 1 | I10: =VLOOKUP(A10,'Data _Transformation'!A9:Q2338,9,FALSE) -> Smoker | J10: =VLOOKUP(A10,'Data _Transformation'!A9:Q2338,10,FALSE) -> Obesity | K10: =VLOOKUP(A10,'Data _Transformation'!A9:Q2338,11,FALSE) -> Diabetes | L10: =VLOOKUP(A10,'Data _Transformation'!A9:Q2338,12,FALSE) -> 37589 | M10: =VLOOKUP(A10,'Data _Transformation'!A9:Q2338,13,FALSE) -> 668 | N10: =VLOOKUP(A10,'Data _Transformation'!A9:Q2338,14,FALSE) -> tier - 3 | O10: =VLOOKUP(A10,'Data _Transformation'!A9:Q2338,15,FALSE) -> tier - 2 | P10: =VLOOKUP(A10,'Data _Transformation'!A9:Q2338,16,0) -> R1012 | Q10: =VLOOKUP(A10,'Data _Transformation'!A9:Q2338,17,0) -> 20
A11: Id10 | B11: =VLOOKUP(A11,'Data _Transformation'!A10:Q2339,2,FALSE) -> Brooke N | C11: =VLOOKUP(A11,'Data _Transformation'!A10:Q2339,3,FALSE) -> 38.06 | D11: =VLOOKUP(A11,'Data _Transformation'!A10:Q2339,4,FALSE) -> 10.79 | E11: =VLOOKUP(A11,'Data _Transformation'!A10:Q2339,5,FALSE) -> No | F11: =VLOOKUP(A11,'Data _Transformation'!A10:Q2339,6,FALSE) -> No | G11: =VLOOKUP(A11,'Data _Transformation'!A10:Q2339,7,FALSE) -> No | H11: =VLOOKUP(A11,'Data _Transformation'!A10:Q2339,8,FALSE) -> 0 | I11: =VLOOKUP(A11,'Data _Transformation'!A10:Q2339,9,FALSE) -> Smoker | J11: =VLOOKUP(A11,'Data _Transformation'!A10:Q2339,10,FALSE) -> Obesity | K11: =VLOOKUP(A11,'Data _Transformation'!A10:Q2339,11,FALSE) -> Diabetes | L11: =VLOOKUP(A11,'Data _Transformation'!A10:Q2339,12,FALSE) -> 35743 | M11: =VLOOKUP(A11,'Data _Transformation'!A10:Q2339,13,FALSE) -> 670 | N11: =VLOOKUP(A11,'Data _Transformation'!A10:Q2339,14,FALSE) -> tier - 3 | O11: =VLOOKUP(A11,'Data _Transformation'!A10:Q2339,15,FALSE) -> tier - 3 | P11: =VLOOKUP(A11,'Data _Transformation'!A10:Q2339,16,0) -> R1013 | Q11: =VLOOKUP(A11,'Data _Transformation'!A10:Q2339,17,0) -> 25
A12: Id11 | B12: =VLOOKUP(A12,'Data _Transformation'!A11:Q2340,2,FALSE) -> Paola Andrea | C12: =VLOOKUP(A12,'Data _Transformation'!A11:Q2340,3,FALSE) -> 37.7 | D12: =VLOOKUP(A12,'Data _Transformation'!A11:Q2340,4,FALSE) -> 5.96 | E12: =VLOOKUP(A12,'Data _Transformation'!A11:Q2340,5,FALSE) -> Yes | F12: =VLOOKUP(A12,'Data _Transformation'!A11:Q2340,6,FALSE) -> No | G12: =VLOOKUP(A12,'Data _Transformation'!A11:Q2340,7,FALSE) -> No | H12: =VLOOKUP(A12,'Data _Transformation'!A11:Q2340,8,FALSE) -> 2 | I12: =VLOOKUP(A12,'Data _Transformation'!A11:Q2340,9,FALSE) -> Smoker | J12: =VLOOKUP(A12,'Data _Transformation'!A11:Q2340,10,FALSE) -> Obesity | K12: =VLOOKUP(A12,'Data _Transformation'!A11:Q2340,11,FALSE) -> Prediabetes | L12: =VLOOKUP(A12,'Data _Transformation'!A11:Q2340,12,FALSE) -> 37146 | M12: =VLOOKUP(A12,'Data _Transformation'!A11:Q2340,13,FALSE) -> 687.54 | N12: =VLOOKUP(A12,'Data _Transformation'!A11:Q2340,14,FALSE) -> tier - 3 | O12: =VLOOKUP(A12,'Data _Transformation'!A11:Q2340,15,FALSE) -> tier - 2 | P12: =VLOOKUP(A12,'Data _Transformation'!A11:Q2340,16,0) -> R1013 | Q12: =VLOOKUP(A12,'Data _Transformation'!A11:Q2340,17,0) -> 21
A13: Id13 | B13: =VLOOKUP(A13,'Data _Transformation'!A12:Q2341,2,FALSE) -> Wade | C13: =VLOOKUP(A13,'Data _Transformation'!A12:Q2341,3,FALSE) -> 40.92 | D13: =VLOOKUP(A13,'Data _Transformation'!A12:Q2341,4,FALSE) -> 8.41 | E13: =VLOOKUP(A13,'Data _Transformation'!A12:Q2341,5,FALSE) -> No | F13: =VLOOKUP(A13,'Data _Transformation'!A12:Q2341,6,FALSE) -> No | G13: =VLOOKUP(A13,'Data _Transformation'!A12:Q2341,7,FALSE) -> No | H13: =VLOOKUP(A13,'Data _Transformation'!A12:Q2341,8,FALSE) -> 0 | I13: =VLOOKUP(A13,'Data _Transformation'!A12:Q2341,9,FALSE) -> Smoker | J13: =VLOOKUP(A13,'Data _Transformation'!A12:Q2341,10,FALSE) -> Obesity | K13: =VLOOKUP(A13,'Data _Transformation'!A12:Q2341,11,FALSE) -> Diabetes | L13: =VLOOKUP(A13,'Data _Transformation'!A12:Q2341,12,FALSE) -> 36508 | M13: =VLOOKUP(A13,'Data _Transformation'!A12:Q2341,13,FALSE) -> 722.99 | N13: =VLOOKUP(A13,'Data _Transformation'!A12:Q2341,14,FALSE) -> tier - 3 | O13: =VLOOKUP(A13,'Data _Transformation'!A12:Q2341,15,FALSE) -> tier - 1 | P13: =VLOOKUP(A13,'Data _Transformation'!A12:Q2341,16,0) -> R1013 | Q13: =VLOOKUP(A13,'Data _Transformation'!A12:Q2341,17,0) -> 23
